Workbook

Sheet bestelltes Materiall
A1: Firma Hebrock Kommission GS Berkel | E1: =SUM(E3:E59) -> 6641.54 | F1: Warenwert ca. Euro Netto
E2: Netto-Preis Sonepar
A3: 06.11.2025 Gs Berkel | B3: 3010118398 | C3: 1009004798 | D3: 1 Cellpack M 15/Euroline/EG Giessharz-Verb | E3: 108.18
A4: 14.10.2025 GS Berkel | B4: 3009538752 | C4: 1009005019 | D4: 100 NIEDAX FLM 6X12 Schraube | E4: 16.05
A5: 31.10.2025 GS Berkel | B5: 3009975320 | C5: 1009005019 | D5: 100 NIEDAX FLM 6X12 Schraube | E5: 16.05
A6: 18.09.2025 | B6: 3009034000 | C6: 1009008680 | D6: 300 OBO BETT. 2026 25 LGR Haft-Clip m.Nagel | E6: 12.69
A7: 11.09.2025 GS Berkel | B7: 3008870486 | C7: 1009009018 | D7: 200 OBO BETT. 2032 SP Kabelklammer | E7: 53.36
A8: 17.10.2025 Gross Berkel | B8: 3009637582 | C8: 1009009018 | D8: 100 OBO BETT. 2032 SP Kabelklammer | E8: 26.68
A9: 27.09.2025 GS Berkel | B9: 3009215892 | C9: 1009012789 | D9: 200 WAGO 243-204 Verbindungsdosenklemme | E9: 26.2
A10: 27.09.2025 GS Berkel | B10: 3009215892 | C10: 1009012790 | D10: 200 WAGO 243-304 Verb.dosenklemme | E10: 26.2
A11: 27.09.2025 GS Berkel | B11: 3009215892 | C11: 1009012791 | D11: 200 WAGO 243-504 Verb.dosenklemme | E11: 26.2
A12: 27.09.2025 GS Berkel | B12: 3009215892 | C12: 1009012792 | D12: 200 WAGO 243-804 Verb.dosenklemme | E12: 26.2
A13: 09.10.2025 Gross Berkel | B13: 3009465848 | C13: 1009017033 | D13: 60 Spelsberg i 12-L Abzweigkasten | E13: 31.16
A14: 18.09.2025 | B14: 3009033800 | C14: 1009017033 | D14: 100 Spelsberg i 12-L Abzweigkasten | E14: 51.94
... A48: 24.10.2025 GS Berkel | B48: 3009820189 | C48: 1010092025 | D48: 300 WAGO 221-413 Compact-Verbindungsklemme | E48: 74.25
A49: 14.10.2025 Gs Berkel | B49: 3009558630 | C49: 1010142889 | D49: 10 NIEDAX SHS 80 S Sammelhalter | E49: 38.47 | F49: im DG
A50: 09.10.2025 Gross Berkel | B50: 3009468651 | C50: 1010370528 | D50: 8 ESYLUX MD 180 BASIC weiss Bewegungsmelde | E50: 167.36
A51: 22.10.2025 GS Berkel | B51: 3009723547 | C51: 1010370528 | D51: 1 ESYLUX MD 180 BASIC weiss Bewegungsmelde | E51: 20.92
A52: 18.09.2025 | B52: 3009033800 | C52: 1010679865 | D52: 200 KAISER 9064-02 Hohlwand Geräte-Verb.dose | E52: 122.44
A53: 09.10.2025 Gross Berkel | B53: 3009465848 | C53: 1010851769 | D53: 2 Walther FW110506CC CEE NEO Wandsteckdose | E53: 12.42
A54: 23.10.2025 GS Berkel | B54: 3009775113 | C54: 1010851769 | D54: 2 Walther FW110506CC CEE NEO Wandsteckdose | E54: 12.42
A55: 03.11.2025 Gross Berkel | B55: 3010012726 | C55: 1010891518 | D55: 50Fränkische FBY-EL-F co2ntrol 25 Kunststo | E55: 21.86
A56: 18.09.2025 | B56: 3009033800 | C56: 1010891518 | D56: 100 Fränkische FBY-EL-F co2ntrol 25 Kunststo | E56: 43.72
A57: 03.11.2025 Gross Berkel | B57: 3010012726 | C57: 1010891519 | D57: 100Fränkische FBY-EL-F co2ntrol 32 Kunststo | E57: 76.17
A58: 23.10.2025 GS Berkel | B58: 3009775113 | C58: 1011378174 | D58: 1 Walther FW130506SK Wandsteckdose | E58: 7.52
A59: 09.10.2025 Gross Berkel | B59: 3009465848 | C59: 1011412720 | D59: 50 Pracht LUNA BL ONE #5800224 LED-Feuchtra | E59: 1660
A60: 24.10.2025 Gs Berkel | B60: 3009821463 | C60: 1011620030 | D60: 4 EVN IC652301204025M LED Strip 25m, mit T | E60: 472

Sheet Leistungsverzeichnis
A1: Pos | B1: Artikel | C1: Bezeichnung | D1: Mengeneinheit | E1: Menge SOLL | F1: Menge IST | G1: Einzelpreis | H1: Gesamt geplant | I1: Gesamt verbaut
C2: 1.0 Allgemeine Vorbemerkungen
C3: 2.0 Beschreibung der Elektrotechnischen Anlage
C4: 3.0 Zusätzliche technische Vorbemerkungen (ZTV)
C5: EDV-Unterstützung
C6: Revisionsunterlagen
C7: KG 440 Starkstromanlagen | H7: =SUM(H8,H38,H85,H235,H265,H273,H294,H523,H549) -> 824668.42 | I7: =SUM(I8,I38,I85,I235,I265,I273,I294,I523,I549) -> 131566.57
A8: 1. 1 | C8: KG 442 Eigenstromversorgungsanlagen | H8: =SUM(H9:H37) -> 107504.52 | I8: =SUM(I9:I37) -> 37943.97
A9: 1. 1. 1 | C9: KG 442 PV-Anlage
A10: 1. 1. 1. 10 | B10: M-Manuell | C10: Photovoltaikmodul | D10: St | E10: 144 | F10: 144 | G10: 134.34 | H10: =SUM(E10*G10) -> 19344.96 | I10: =SUM(G10*F10) -> 19344.96
A11: 1. 1. 1. 20 | B11: M-Manuell | C11: Aufdachmontagesystem in Alu schwarz | D11: St | E11: 4 | F11: 4 | G11: 4083.74 | H11: =SUM(E11*G11) -> 16334.96 | I11: =SUM(G11*F11) -> 16334.96
A12: 1. 1. 1. 30 | B12: M-Manuell | C12: Wechselrichter 3phas. für vorgenannte Anlage | D12: St | E12: 2 | G12: 3762.53 | H12: =SUM(E12*G12) -> 7525.06 | I12: =SUM(G12*F12) -> 0
A13: 1. 1. 1. 40 | B13: M-Manuell | C13: Wechselrichter | D13: St | E13: 1 | G13: 3594.94 | H13: =SUM(E13*G13) -> 3594.94 | I13: =SUM(G13*F13) -> 0
A14: 1. 1. 1. 50 | B14: M-Manuell | C14: Batteriespeicher | D14: St | E14: 2 | G14: 4318.72 | H14: =SUM(E14*G14) -> 8637.44 | I14: =SUM(G14*F14) -> 0
C15: Kabel und Leitungsnetz
A16: 1. 1. 1. 60 | B16: M-Manuell | C16: DC-Kabel rot 6 mm² | D16: m | E16: 720 | F16: 100 | G16: 4.07 | H16: =SUM(E16*G16) -> 2930.4 | I16: =SUM(G16*F16) -> 407
A17: 1. 1. 1. 70 | B17: M-Manuell | C17: DC Kabel schwarz 6 mm² | D17: m | E17: 720 | F17: 100 | G17: 4.07 | H17: =SUM(E17*G17) -> 2930.4 | I17: =SUM(G17*F17) -> 407
A18: 1. 1. 1. 80 | B18: M-Manuell | C18: Anlagenerdung | D18: St | E18: 4 | F18: 4 | G18: 260.4 | H18: =SUM(E18*G18) -> 1041.6 | I18: =SUM(G18*F18) -> 1041.6
A20: 1. 1. 1. 90 | B20: M-Manuell | C20: Aluminiumrohr, schwer M 32 | D20: m | E20: 60 | G20: 22.19 | H20: =SUM(E20*G20) -> 1331.4 | I20: =SUM(G20*F20) -> 0
A21: 1. 1. 1. 100 | B21: M-Manuell | C21: Kunststoff-Stangenrohr M 32 | D21: m | E21: 36 | G21: 16.99 | H21: =SUM(E21*G21) -> 611.64 | I21: =SUM(G21*F21) -> 0
A22: 1. 1. 1. 110 | B22: M-Manuell | C22: Kuststoff-Wellrohr schwarz 40mm | D22: m | E22: 40 | G22: 7.33 | H22: =SUM(E22*G22) -> 293.2 | I22: =SUM(G22*F22) -> 0
A23: 1. 1. 1. 120 | B23: M-Manuell | C23: Inst-Kanal 40x40 | D23: m | E23: 6 | G23: 12.46 | H23: =SUM(E23*G23) -> 74.76 | I23: =SUM(G23*F23) -> 0
A24: 1. 1. 1. 130 | B24: M-Manuell | C24: Inst-Kanal 40x90 | D24: m | E24: 12 | G24: 24.41 | H24: =SUM(E24*G24) -> 292.92 | I24: =SUM(G24*F24) -> 0
A25: 1. 1. 1. 140 | B25: M-Manuell | C25: Brandschutzkanal I90 | D25: m | E25: 82 | G25: 185.45 | H25: =SUM(E25*G25) -> 15206.9 | I25: =SUM(G25*F25) -> 0
A26: 1. 1. 1. 150 | B26: M-Manuell | C26: Brandschutzkanal I90 | D26: m | E26: 48 | G26: 167.21 | H26: =SUM(E26*G26) -> 8026.08 | I26: =SUM(G26*F26) -> 0
A27: 1. 1. 1. 160 | B27: M-Manuell | C27: Ltg. NYM-J 5x6 | D27: m | E27: 60 | F27: 35 | G27: 11.67 | H27: =SUM(E27*G27) -> 700.2 | I27: =SUM(G27*F27) -> 408.45
A28: 1. 1. 1. 170 | B28: M-Manuell | C28: Ltg. NYM-J 5x35 | D28: m | E28: 48 | G28: 65.48 | H28: =SUM(E28*G28) -> 3143.04 | I28: =SUM(G28*F28) -> 0
A29: 1. 1. 1. 180 | B29: M-Manuell | C29: Kat.7 4x2xAWG23 | D29: m | E29: 50 | G29: 3.87 | H29: =SUM(E29*G29) -> 193.5 | I29: =SUM(G29*F29) -> 0
C30: Sonstiges
A31: 1. 1. 1. 190 | B31: M-Manuell | C31: Generatoranschlusskasten für 2 Stränge je MPP | D31: St | E31: 4 | G31: 403.48 | H31: =SUM(E31*G31) -> 1613.92 | I31: =SUM(G31*F31) -> 0
A32: 1. 1. 1. 200 | B32: M-Manuell | C32: Fernschalter | D32: St | E32: 1 | G32: 2571.5 | H32: =SUM(E32*G32) -> 2571.5 | I32: =SUM(G32*F32) -> 0
A33: 1. 1. 1. 210 | B33: M-Manuell | C33: Netz- und Anlagenschutz | D33: St | E33: 1 | G33: 2053.1 | H33: =SUM(E33*G33) -> 2053.1 | I33: =SUM(G33*F33) -> 0
A34: 1. 1. 1. 220 | B34: M-Manuell | C34: Antragsformalitäten | D34: psch | E34: 1 | G34: 700 | H34: =SUM(E34*G34) -> 700 | I34: =SUM(G34*F34) -> 0
A35: 1. 1. 1. 230 | B35: M-Manuell | C35: Inbetriebnahme | D35: psch | E35: 1 | G35: 908.5 | H35: =SUM(E35*G35) -> 908.5 | I35: =SUM(G35*F35) -> 0
A36: 1. 1. 1. 240 | B36: M-Manuell | C36: SmartMeter | D36: St | E36: 1 | G36: 365.7 | H36: =SUM(E36*G36) -> 365.7 | I36: =SUM(G36*F36) -> 0
A37: 1. 1. 1. 250 | B37: M-Manuell | C37: Wartung | D37: St | E37: 4 | G37: 1769.6 | H37: =SUM(E37*G37) -> 7078.4 | I37: =SUM(G37*F37) -> 0
A38: 1. 2 | C38: KG 443 Niederspannnungsschaltanlagen | H38: =SUM(H39:H84) -> 44769.2 | I38: =SUM(I39:I84) -> 0
A39: 1. 2. 1 | C39: KG 443 Verteilungen
A40: 1. 2. 1. 10 | B40: M-Manuell | C40: Niederspannungshauptverteilung | D40: St | E40: 1 | G40: 2190.05 | H40: =SUM(E40*G40) -> 2190.05 | I40: =SUM(G40*F40) -> 0
A41: 1. 2. 1. 20 | B41: M-Manuell | C41: Unterverteilung | D41: St | E41: 2 | G41: 2718.47 | H41: =SUM(E41*G41) -> 5436.94 | I41: =SUM(G41*F41) -> 0
...

Sheet Kabel
A1: Pos | B1: Artikel | C1: Bezeichnung | D1: Mengeneinheit | E1: Menge SOLL | F1: Menge IST | G1: Einzelpreis | H1: Gesamt
C3: Auf Baustelle | E3: Menge bestellt | F3: Menge verbaut | I3: plus % | J3: %
A4: Kumulierte bestellte/ verbaute Menge | C4: NYM 3x1,5 | D4: m | E4: 1000 | F4: 350 | G4: 3.72 | H4: =G4*F4 -> 1302 | I4: =SUM(H4*J4) -> 1692.6 | J4: 1.3
C5: NYM 3x2,5 | D5: m | E5: 3000 | F5: 2000 | G5: 4.17 | H5: =G5*F5 -> 8340 | I5: =SUM(H5*J5) -> 10842 | J5: 1.3
C6: NYM 5x1,5 | D6: m | E6: 1500 | F6: 1500 | G6: 4.19 | H6: =G6*F6 -> 6285 | I6: =SUM(H6*J6) -> 8170.5 | J6: 1.3
C7: NYM 5x6 | D7: m | E7: 15 | F7: 0 | G7: 11.67 | H7: =G7*F7 -> 0 | I7: =SUM(H7*J7) -> 0 | J7: 1.3
C8: BMK YSTY 2x2x0,8 | D8: m | E8: 100 | F8: 100 | G8: 3.39 | H8: =G8*F8 -> 339 | I8: =SUM(H8*J8) -> 440.7 | J8: 1.3
C9: BUS KNX 2x2x0,8 | D9: m | E9: 1000 | F9: 1000 | G9: 3.1 | H9: =G9*F9 -> 3100 | I9: =SUM(H9*J9) -> 4030 | J9: 1.3
C10: DATEN SIMPLEX | D10: m | E10: 500 | F10: 500 | G10: 4.4 | H10: =G10*F10 -> 2200 | I10: =SUM(H10*J10) -> 2860 | J10: 1.3
C11: ELA YSTY 4x2x0,8 | D11: m | E11: 500 | F11: 500 | G11: 3.78 | H11: =G11*F11 -> 1890 | I11: =SUM(H11*J11) -> 2457 | J11: 1.3
C12: DATEN CAT 7 Erdkabel | D12: m | E12: 0 | F12: 0 | G12: 4 | H12: =G12*F12 -> 0 | I12: =SUM(H12*J12) -> 0 | J12: 1.3
C13: DATEN DUPLEX | D13: m | E13: 2000 | F13: 2000 | G13: 5.37 | H13: =G13*F13 -> 10740 | I13: =SUM(H13*J13) -> 13962 | J13: 1.3
C14: NYCWY 4x150 | D14: m | E14: 0 | F14: 0 | G14: 148.46 | H14: =G14*F14 -> 0 | I14: =SUM(H14*J14) -> 0 | J14: 1.3
C15: NYCWY 4x25 | D15: m | E15: 0 | F15: 0 | G15: 56.54 | H15: =G15*F15 -> 0 | I15: =SUM(H15*J15) -> 0 | J15: 1.3
C16: NYCWY 4x35 | D16: m | E16: 0 | F16: 0 | G16: 40.97 | H16: =G16*F16 -> 0 | I16: =SUM(H16*J16) -> 0 | J16: 1.3
... C20: DAE JEHStH E30 4x2x0,8rt | D20: m | E20: 210 | F20: 0 | G20: 6.66 | H20: =G20*F20 -> 0 | I20: =SUM(H20*J20) -> 0 | J20: 1.3
C21: NYM 5x25 | D21: m | E21: 0 | F21: 0 | H21: =G21*F21 -> 0 | I21: =SUM(H21*J21) -> 0 | J21: 1.3
C22: DAE JEHStH E30 2x2x0,8rt | D22: m | E22: 500 | F22: 500 | G22: 6.66 | H22: =G22*F22 -> 3330 | I22: =SUM(H22*J22) -> 4329 | J22: 1.3
C23: Brandschutzdose | D23: Stk. | E23: 50 | F23: 50 | G23: 31.53 | H23: =G23*F23 -> 1576.5 | I23: =SUM(H23*J23) -> 2049.45 | J23: 1.3
C24: BMK YSTY 10x2x0,8 | D24: m | E24: 100 | F24: 100 | G24: 4.96 | H24: =G24*F24 -> 496 | I24: =SUM(H24*J24) -> 644.8 | J24: 1.3
C25: SHS 15 Sammelhalter | D25: Stk. | E25: 100 | F25: 100 | G25: 10.83 | H25: =G25*F25 -> 1083 | I25: =SUM(H25*J25) -> 1407.9 | J25: 1.3
H26: =G26*F26 -> 0 | I26: =SUM(H26*J26) -> 0 | J26: 1.3
H27: =G27*F27 -> 0 | I27: =SUM(H27*J27) -> 0 | J27: 1.3
H28: =G28*F28 -> 0 | I28: =SUM(H28*J28) -> 0 | J28: 1.3
H29: =G29*F29 -> 0 | I29: =SUM(H29*J29) -> 0 | J29: 1.3
H34: =SUM(H4:H33) -> 48644 | I34: =SUM(I4:I33) -> 63237.2
E37: Summe Verlegt | H37: =SUM('TR.3 Kabel 1.OG Teil 1'!A8+'TR.3 1.OG Kabel Teil 2'!A8) -> 0

Sheet TR.3 Kabel 1.OG Teil 1
A2: Summe Meter bestellt | C2: =Kabel!E7 -> 15 | G2: =Kabel!E4 -> 1000 | K2: =Kabel!E5 -> 3000 | O2: =Kabel!E17 -> 950 | S2: =Kabel!E6 -> 1500 | W2: =Kabel!E18 -> 500 | AA2: =Kabel!E9 -> 1000 | AE2: =Kabel!E13 -> 2000 | AI2: =Kabel!E10 -> 500 | AM2: =Kabel!E11 -> 500 | AQ2: =Kabel!E8 -> 100 | AU2: =Kabel!E24 -> 100 | AY2: =Kabel!E20 -> 210 | AZ2: =Kabel!E23 -> 50
A3: Summe Meter gemeldet | C3: =Kabel!F7 -> 0 | G3: =Kabel!F4 -> 350 | K3: =Kabel!F5 -> 2000 | O3: =Kabel!F17 -> 950 | S3: =Kabel!F6 -> 1500 | W3: =Kabel!F18 -> 500 | AA3: =Kabel!F9 -> 1000 | AE3: =Kabel!F13 -> 2000 | AI3: =Kabel!F10 -> 500 | AM3: =Kabel!F11 -> 500 | AQ3: =Kabel!F8 -> 100 | AU3: =Kabel!F24 -> 100 | AZ3: =Kabel!F23 -> 50
A4: Summe Meter Aufmaß | C4: =SUM(C9+'TR.3 1.OG Kabel Teil 2'!C9) -> 0 | G4: =SUM(G9+'TR.3 1.OG Kabel Teil 2'!G9) -> 0 | K4: =SUM(K9+'TR.3 1.OG Kabel Teil 2'!K9) -> 0 | O4: =SUM(O9+'TR.3 1.OG Kabel Teil 2'!O9) -> 0 | S4: =SUM(S9+'TR.3 1.OG Kabel Teil 2'!S9) -> 0 | W4: =SUM(W9+'TR.3 1.OG Kabel Teil 2'!W9) -> 0 | AA4: =SUM(AA9+'TR.3 1.OG Kabel Teil 2'!AA9) -> 0 | AE4: =SUM(AE9+'TR.3 1.OG Kabel Teil 2'!AE9) -> 0 | AI4: =SUM(AI9+'TR.3 1.OG Kabel Teil 2'!AI9) -> 0 | AM4: =SUM(AM9+'TR.3 1.OG Kabel Teil 2'!AM9) -> 0 | AQ4: =SUM(AQ9+'TR.3 1.OG Kabel Teil 2'!AQ9) -> 0 | AU4: =SUM(AU9+'TR.3 1.OG Kabel Teil 2'!AU9) -> 0 | AY4: =SUM(AY9+'TR.3 1.OG Kabel Teil 2'!AY9) -> 0 | AZ4: =SUM(AZ9+'TR.3 1.OG Kabel Teil 2'!AZ9) -> 0
B5: Ltg. NYM-J 5x6 | C5: NYM 5x6 | D5: NYM-J 3x1,5 Montagewand | E5: NYM-J 3x1,5 vorh.Kabelrinne/ Kanal | F5: NYM-J 3x1,5 oberhalb Zwischendecke | G5: NYM 3x1,5 | H5: NYM-J 3x2,5 Montagewand | I5: NYM-J 3x2,5 vorh.Kabelrinne/ Kanal | J5: NYM-J 3x2,5 oberhalb Zwischendecke | K5: NYM 3x2,5 | L5: NYM-J 3x4 Montagewand | M5: NYM-J 3x4 vorh.Kabelrinne/ Kanal | N5: NYM-J 3x4 oberhalb Zwischendecke | O5: NYM 3x4 | P5: NYM-J 5x1,5 Montagewand | Q5: NYM-J 5x1,5 vorh.Kabelrinne/ Kanal | R5: NYM-J 5x1,5 oberhalb Zwischendecke | S5: NYM 5x1,5 | T5: NYM-J 5x2,5 Montagewand | U5: NYM-J 5x2,5 vorh.Kabelrinne/ Kanal | V5: NYM-J 5x2,5 oberhalb Zwischendecke | W5: NYM 5x2,5 | X5: KNX-TP YCYM 2x2x0,8 Montagewand | Y5: KNX-TP YCYM 2x2x0,8 vorh.Kabelrinne/ Kanal | Z5: KNX-TP YCYM 2x2x0,8 oberhalb Zwischendecke | AA5: KNX 2x2x0,8 | AB5: Kat.6A ungeschirmt 4x2xAWG23 Montagewand | AC5: Kat.6A ungeschirmt 4x2xAWG23 vorh.Kabelrinne/ Kanal | AD5: Kat.6A ungeschirmt 4x2xAWG23 oberhalb Zwischendecke | AE5: Daten Kat Duplex | AF5: Kat.6A ungeschirmt 4x2xAWG23 Montagewand | AG5: Kat.6A ungeschirmt 4x2xAWG23 vorh.Kabelrinne/ Kanal | AH5: Kat.6A ungeschirmt 4x2xAWG23 oberhalb Zwischendecke | AI5: Daten Kat Simplex | AJ5: ELA J-Y(St)Y 4x2x0,8 Bd Montagewand | AK5: ELA J-Y(St)Y 4x2x0,8 Bd vorh.Kabelrinne/ Kanal | AL5: ELA J-Y(St)Y 4x2x0,8 Bd oberhalb Zwischendecke | AM5: ELA 4x2x0,8 | AN5: BMK J-Y(St)Y 2x2x0,8 Montagewand | AO5: BMK J-Y(St)Y 2x2x0,8 vorh.Kabelrinne/ Kanal | AP5: BMK J-Y(St)Y 2x2x0,8 oberhalb Zwischendecke | AQ5: BMK 2x2x0,8 | AR5: BMK J-Y(St)Y 10x2x0,8 Montagewand | AS5: BMK J-Y(St)Y 10x2x0,8 vorh.Kabelrinne/ Kanal | AT5: BMK J-Y(St)Y 10x2x0,8 oberhalb Zwischendecke | AU5: BMK 10x2x0,8 für Feuerwehr | AV5: E30 JE-H(St)H 4x2x0,8 Bd Montagewand | AW5: E30 JE-H(St)H 4x2x0,8 Bd vorh.Kabelrinne/ Kanal | AX5: E30 JE-H(St)H 4x2x0,8 Bd oberhalb Zwischendecke | AY5: E30 4x2x0,8 | AZ5: Brandschutzdose | BA5: Brandschutzdose
B6: 1. 1. 1. 160 | D6: 1.3.3.702 | E6: 1.3.3.703 | F6: 1.3.3.705 | H6: 1.3.3.720 | I6: 1.3.3.721 | J6: 1.3.3.723 | L6: 1.3.3.763 | M6: 1.3.3.764 | N6: 1.3.3.765 | P6: 1.3.3.711 | Q6: 1.3.3.712 | R6: 1.3.3.714 | T6: 1.3.3.729 | U6: 1.3.3.730 | V6: 1.3.3.732 | X6: 3. 1. 1. 160 | Y6: 3. 1. 1. 170 | Z6: 3. 1. 1. 190 | AB6: 2. 4. 3. 90 | AC6: 2. 4. 3. 100 | AD6: 2. 4. 3. 120 | AF6: 2. 4. 3. 90 | AG6: 2. 4. 3. 100 | AH6: 2. 4. 3. 120 | AJ6: 2. 4. 1. 210 | AK6: 2. 4. 1. 220 | AL6: 2. 4. 1. 240 | AN6: 2. 4. 1. 370 | AO6: 2. 4. 1. 390 | AP6: 2. 4. 1. 410 | AR6: 2. 4. 1. 590 | AS6: 2. 4. 1. 600 | AT6: 2. 4. 1. 620 | AV6: 2. 4. 1. 670 | AW6: 2. 4. 1. 680 | AX6: 2. 4. 1. 700 | AZ6: 1.3.4.40
B7: 11.67 | D7: 3.72 | E7: 3.72 | F7: 3.72 | H7: 4.17 | I7: 4.17 | J7: 4.17 | L7: 5.75 | M7: 5.75 | N7: 5.75 | P7: 4.19 | Q7: 4.19 | R7: 4.19 | T7: 5 | U7: 5 | V7: 5 | X7: 3.1 | Y7: 3.1 | Z7: 3.55 | AB7: 3.2 | AC7: 3.2 | AD7: 3.2 | AF7: 4.4 | AG7: 4.4 | AH7: 4.4 | AJ7: 3.78 | AK7: 3.78 | AL7: 3.99 | AN7: 3.39 | AO7: 3.39 | AP7: 3.59 | AR7: 4.96 | AS7: 4.96 | AT7: 5.11 | AV7: 6.66 | AW7: 6.66 | AX7: 11.6 | AZ7: 31.53
A8: =SUM(B8:BC8) -> 0 | B8: =B9*B7 -> 0 | D8: =D9*D7 -> 0 | E8: =E9*E7 -> 0 | F8: =F9*F7 -> 0 | H8: =H9*H7 -> 0 | I8: =I9*I7 -> 0 | J8: =J9*J7 -> 0 | L8: =L9*L7 -> 0 | M8: =M9*M7 -> 0 | N8: =N9*N7 -> 0 | P8: =P9*P7 -> 0 | Q8: =Q9*Q7 -> 0 | R8: =R9*R7 -> 0 | T8: =T9*T7 -> 0 | U8: =U9*U7 -> 0 | V8: =V9*V7 -> 0 | X8: =X9*X7 -> 0 | Y8: =Y9*Y7 -> 0 | Z8: =Z9*Z7 -> 0 | AB8: =AB9*AB7 -> 0 | AC8: =AC9*AC7 -> 0 | AD8: =AD9*AD7 -> 0 | AF8: =AF9*AF7 -> 0 | AG8: =AG9*AG7 -> 0 | AH8: =AH9*AH7 -> 0 | AJ8: =AJ9*AJ7 -> 0 | AK8: =AK9*AK7 -> 0 | AL8: =AL9*AL7 -> 0 | AN8: =AN9*AN7 -> 0 | AO8: =AO9*AO7 -> 0 | AP8: =AP9*AP7 -> 0 | AR8: =AR9*AR7 -> 0 | AS8: =AS9*AS7 -> 0 | AT8: =AT9*AT7 -> 0 | AV8: =AV9*AV7 -> 0 | AW8: =AW9*AW7 -> 0 | AX8: =AX9*AX7 -> 0 | AZ8: =AZ9*AZ7 -> 0
B9: =SUM(B14:B268) -> 0 | C9: =SUM(B9) -> 0 | D9: =SUM(D14:D268) -> 0 | E9: =SUM(E14:E268) -> 0 | F9: =SUM(F14:F268) -> 0 | G9: =SUM(D9:F9) -> 0 | H9: =SUM(H14:H268) -> 0 | I9: =SUM(I14:I268) -> 0 | J9: =SUM(J14:J268) -> 0 | K9: =SUM(H9:J9) -> 0 | L9: =SUM(L14:L268) -> 0 | M9: =SUM(M14:M268) -> 0 | N9: =SUM(N14:N268) -> 0 | O9: =SUM(L9:N9) -> 0 | P9: =SUM(P14:P268) -> 0 | Q9: =SUM(Q14:Q268) -> 0 | R9: =SUM(R14:R268) -> 0 | S9: =SUM(P9:R9) -> 0 | T9: =SUM(T14:T268) -> 0 | U9: =SUM(U14:U268) -> 0 | V9: =SUM(V14:V268) -> 0 | W9: =SUM(T9:V9) -> 0 | X9: =SUM(X14:X268) -> 0 | Y9: =SUM(Y14:Y268) -> 0 | Z9: =SUM(Z14:Z268) -> 0 | AA9: =SUM(X9:Z9) -> 0 | AB9: =SUM(AB14:AB268) -> 0 | AC9: =SUM(AC14:AC268) -> 0 | AD9: =SUM(AD14:AD268) -> 0 | AE9: =SUM(AB9:AD9) -> 0 | AF9: =SUM(AF14:AF268) -> 0 | AG9: =SUM(AG14:AG268) -> 0 | AH9: =SUM(AH14:AH268) -> 0 | AI9: =SUM(AF9:AH9) -> 0 | AJ9: =SUM(AJ14:AJ268) -> 0 | AK9: =SUM(AK14:AK268) -> 0 | AL9: =SUM(AL14:AL268) -> 0 | AM9: =SUM(AJ9:AL9) -> 0 | AN9: =SUM(AN14:AN268) -> 0 | AO9: =SUM(AO14:AO268) -> 0 | AP9: =SUM(AP14:AP268) -> 0 | AQ9: =SUM(AN9:AP9) -> 0 | AR9: =SUM(AR14:AR268) -> 0 | AS9: =SUM(AS14:AS268) -> 0 | AT9: =SUM(AT14:AT268) -> 0 | AU9: =SUM(AR9:AT9) -> 0 | AV9: =SUM(AV14:AV268) -> 0 | AW9: =SUM(AW14:AW268) -> 0 | AX9: =SUM(AX14:AX268) -> 0 | AY9: =SUM(AV9:AX9) -> 0 | AZ9: =SUM(AZ14:AZ175) -> 0
A10: A.2.22 - UV 05 EG Unterrichtsbereich
A12: Kabel/ Stromkreis

Sheet TR.3 1.OG Kabel Teil 2
A2: Summe Meter bestellt | C2: =Kabel!E7 -> 15 | G2: =Kabel!E4 -> 1000 | K2: =Kabel!E5 -> 3000 | O2: =Kabel!E17 -> 950 | S2: =Kabel!E6 -> 1500 | W2: =Kabel!E18 -> 500 | AA2: =Kabel!E9 -> 1000 | AE2: =Kabel!E13 -> 2000 | AI2: =Kabel!E10 -> 500 | AM2: =Kabel!E11 -> 500 | AQ2: =Kabel!E8 -> 100 | AU2: =Kabel!E24 -> 100 | AY2: =Kabel!E20 -> 210 | AZ2: =Kabel!E23 -> 50
A3: Summe Meter gemeldet | C3: =Kabel!F7 -> 0 | G3: =Kabel!F4 -> 350 | K3: =Kabel!F5 -> 2000 | O3: =Kabel!F17 -> 950 | S3: =Kabel!F6 -> 1500 | W3: =Kabel!F18 -> 500 | AA3: =Kabel!F9 -> 1000 | AE3: =Kabel!F13 -> 2000 | AI3: =Kabel!F10 -> 500 | AM3: =Kabel!F11 -> 500 | AQ3: =Kabel!F8 -> 100 | AU3: =Kabel!F24 -> 100 | AZ3: =Kabel!F23 -> 50
A4: Summe Meter Aufmaß | C4: =SUM(C9+'TR.3 Kabel 1.OG Teil 1'!C9) -> 0 | G4: =SUM(G9+'TR.3 Kabel 1.OG Teil 1'!G9) -> 0 | K4: =SUM(K9+'TR.3 Kabel 1.OG Teil 1'!K9) -> 0 | O4: =SUM(O9+'TR.3 Kabel 1.OG Teil 1'!O9) -> 0 | S4: =SUM(S9+'TR.3 Kabel 1.OG Teil 1'!S9) -> 0 | W4: =SUM(W9+'TR.3 Kabel 1.OG Teil 1'!W9) -> 0 | AA4: =SUM(AA9+'TR.3 Kabel 1.OG Teil 1'!AA9) -> 0 | AE4: =SUM(AE9+'TR.3 Kabel 1.OG Teil 1'!AE9) -> 0 | AI4: =SUM(AI9+'TR.3 Kabel 1.OG Teil 1'!AI9) -> 0 | AM4: =SUM(AM9+'TR.3 Kabel 1.OG Teil 1'!AM9) -> 0 | AQ4: =SUM(AQ9+'TR.3 Kabel 1.OG Teil 1'!AQ9) -> 0 | AU4: =SUM(AU9+'TR.3 Kabel 1.OG Teil 1'!AU9) -> 0 | AY4: =SUM(AY9+'TR.3 Kabel 1.OG Teil 1'!AY9) -> 0 | AZ4: =SUM(AZ9+'TR.3 Kabel 1.OG Teil 1'!AZ9) -> 0
B5: Ltg. NYM-J 5x6 | C5: NYM 5x6 | D5: NYM-J 3x1,5 Montagewand | E5: NYM-J 3x1,5 vorh.Kabelrinne/ Kanal | F5: NYM-J 3x1,5 oberhalb Zwischendecke | G5: NYM 3x1,5 | H5: NYM-J 3x2,5 Montagewand | I5: NYM-J 3x2,5 vorh.Kabelrinne/ Kanal | J5: NYM-J 3x2,5 oberhalb Zwischendecke | K5: NYM 3x2,5 | L5: NYM-J 3x4 Montagewand | M5: NYM-J 3x4 vorh.Kabelrinne/ Kanal | N5: NYM-J 3x4 oberhalb Zwischendecke | O5: NYM 3x4 | P5: NYM-J 5x1,5 Montagewand | Q5: NYM-J 5x1,5 vorh.Kabelrinne/ Kanal | R5: NYM-J 5x1,5 oberhalb Zwischendecke | S5: NYM 5x1,5 | T5: NYM-J 5x2,5 Montagewand | U5: NYM-J 5x2,5 vorh.Kabelrinne/ Kanal | V5: NYM-J 5x2,5 oberhalb Zwischendecke | W5: NYM 5x2,5 | X5: KNX-TP YCYM 2x2x0,8 Montagewand | Y5: KNX-TP YCYM 2x2x0,8 vorh.Kabelrinne/ Kanal | Z5: KNX-TP YCYM 2x2x0,8 oberhalb Zwischendecke | AA5: KNX 2x2x0,8 | AB5: Kat.6A ungeschirmt 4x2xAWG23 Montagewand | AC5: Kat.6A ungeschirmt 4x2xAWG23 vorh.Kabelrinne/ Kanal | AD5: Kat.6A ungeschirmt 4x2xAWG23 oberhalb Zwischendecke | AE5: Daten Kat Duplex | AF5: Kat.6A ungeschirmt 4x2xAWG23 Montagewand | AG5: Kat.6A ungeschirmt 4x2xAWG23 vorh.Kabelrinne/ Kanal | AH5: Kat.6A ungeschirmt 4x2xAWG23 oberhalb Zwischendecke | AI5: Daten Kat Simplex | AJ5: ELA J-Y(St)Y 4x2x0,8 Bd Montagewand | AK5: ELA J-Y(St)Y 4x2x0,8 Bd vorh.Kabelrinne/ Kanal | AL5: ELA J-Y(St)Y 4x2x0,8 Bd oberhalb Zwischendecke | AM5: ELA 4x2x0,8 | AN5: BMK J-Y(St)Y 2x2x0,8 Montagewand | AO5: BMK J-Y(St)Y 2x2x0,8 vorh.Kabelrinne/ Kanal | AP5: BMK J-Y(St)Y 2x2x0,8 oberhalb Zwischendecke | AQ5: BMK 2x2x0,8 | AR5: BMK J-Y(St)Y 10x2x0,8 Montagewand | AS5: BMK J-Y(St)Y 10x2x0,8 vorh.Kabelrinne/ Kanal | AT5: BMK J-Y(St)Y 10x2x0,8 oberhalb Zwischendecke | AU5: BMK 10x2x0,8 für Feuerwehr | AV5: E30 JE-H(St)H 4x2x0,8 Bd Montagewand | AW5: E30 JE-H(St)H 4x2x0,8 Bd vorh.Kabelrinne/ Kanal | AX5: E30 JE-H(St)H 4x2x0,8 Bd oberhalb Zwischendecke | AY5: E30 4x2x0,8 | AZ5: Brandschutzdose | BA5: Brandschutzdose
B6: 1. 1. 1. 160 | D6: 1.3.3.702 | E6: 1.3.3.703 | F6: 1.3.3.705 | H6: 1.3.3.720 | I6: 1.3.3.721 | J6: 1.3.3.723 | L6: 1.3.3.763 | M6: 1.3.3.764 | N6: 1.3.3.765 | P6: 1.3.3.711 | Q6: 1.3.3.712 | R6: 1.3.3.714 | T6: 1.3.3.729 | U6: 1.3.3.730 | V6: 1.3.3.732 | X6: 3. 1. 1. 160 | Y6: 3. 1. 1. 170 | Z6: 3. 1. 1. 190 | AB6: 2. 4. 3. 90 | AC6: 2. 4. 3. 100 | AD6: 2. 4. 3. 120 | AF6: 2. 4. 3. 90 | AG6: 2. 4. 3. 100 | AH6: 2. 4. 3. 120 | AJ6: 2. 4. 1. 210 | AK6: 2. 4. 1. 220 | AL6: 2. 4. 1. 240 | AN6: 2. 4. 1. 370 | AO6: 2. 4. 1. 390 | AP6: 2. 4. 1. 410 | AR6: 2. 4. 1. 590 | AS6: 2. 4. 1. 600 | AT6: 2. 4. 1. 620 | AV6: 2. 4. 1. 670 | AW6: 2. 4. 1. 680 | AX6: 2. 4. 1. 700 | AZ6: 1.3.4.40
B7: 11.67 | D7: 3.72 | E7: 3.72 | F7: 3.72 | H7: 4.17 | I7: 4.17 | J7: 4.17 | L7: 5.75 | M7: 5.75 | N7: 5.75 | P7: 4.19 | Q7: 4.19 | R7: 4.19 | T7: 5 | U7: 5 | V7: 5 | X7: 3.1 | Y7: 3.1 | Z7: 3.55 | AB7: 3.2 | AC7: 3.2 | AD7: 3.2 | AF7: 4.4 | AG7: 4.4 | AH7: 4.4 | AJ7: 3.78 | AK7: 3.78 | AL7: 3.99 | AN7: 3.39 | AO7: 3.39 | AP7: 3.59 | AR7: 4.96 | AS7: 4.96 | AT7: 5.11 | AV7: 6.66 | AW7: 6.66 | AX7: 11.6 | AZ7: 31.53
A8: =SUM(B8:BB8) -> 0 | B8: =B9*B7 -> 0 | D8: =D9*D7 -> 0 | E8: =E9*E7 -> 0 | F8: =F9*F7 -> 0 | H8: =H9*H7 -> 0 | I8: =I9*I7 -> 0 | J8: =J9*J7 -> 0 | L8: =L9*L7 -> 0 | M8: =M9*M7 -> 0 | N8: =N9*N7 -> 0 | P8: =P9*P7 -> 0 | Q8: =Q9*Q7 -> 0 | R8: =R9*R7 -> 0 | T8: =T9*T7 -> 0 | U8: =U9*U7 -> 0 | V8: =V9*V7 -> 0 | X8: =X9*X7 -> 0 | Y8: =Y9*Y7 -> 0 | Z8: =Z9*Z7 -> 0 | AB8: =AB9*AB7 -> 0 | AC8: =AC9*AC7 -> 0 | AD8: =AD9*AD7 -> 0 | AF8: =AF9*AF7 -> 0 | AG8: =AG9*AG7 -> 0 | AH8: =AH9*AH7 -> 0 | AJ8: =AJ9*AJ7 -> 0 | AK8: =AK9*AK7 -> 0 | AL8: =AL9*AL7 -> 0 | AN8: =AN9*AN7 -> 0 | AO8: =AO9*AO7 -> 0 | AP8: =AP9*AP7 -> 0 | AR8: =AR9*AR7 -> 0 | AS8: =AS9*AS7 -> 0 | AT8: =AT9*AT7 -> 0 | AV8: =AV9*AV7 -> 0 | AW8: =AW9*AW7 -> 0 | AX8: =AX9*AX7 -> 0 | AZ8: =AZ9*AZ7 -> 0
B9: =SUM(B14:B176) -> 0 | C9: =SUM(B9) -> 0 | D9: =SUM(D14:D176) -> 0 | E9: =SUM(E14:E176) -> 0 | F9: =SUM(F14:F176) -> 0 | G9: =SUM(D9:F9) -> 0 | H9: =SUM(H14:H176) -> 0 | I9: =SUM(I14:I176) -> 0 | J9: =SUM(J14:J176) -> 0 | K9: =SUM(H9:J9) -> 0 | L9: =SUM(L14:L180) -> 0 | M9: =SUM(M14:M180) -> 0 | N9: =SUM(N14:N180) -> 0 | O9: =SUM(L9:N9) -> 0 | P9: =SUM(P14:P176) -> 0 | Q9: =SUM(Q14:Q176) -> 0 | R9: =SUM(R14:R176) -> 0 | S9: =SUM(P9:R9) -> 0 | T9: =SUM(T14:T176) -> 0 | U9: =SUM(U14:U176) -> 0 | V9: =SUM(V14:V176) -> 0 | W9: =SUM(T9:V9) -> 0 | X9: =SUM(X14:X176) -> 0 | Y9: =SUM(Y14:Y176) -> 0 | Z9: =SUM(Z14:Z176) -> 0 | AA9: =SUM(X9:Z9) -> 0 | AB9: =SUM(AB14:AB176) -> 0 | AC9: =SUM(AC14:AC176) -> 0 | AD9: =SUM(AD14:AD176) -> 0 | AE9: =SUM(AB9:AD9) -> 0 | AF9: =SUM(AF14:AF180) -> 0 | AG9: =SUM(AG14:AG180) -> 0 | AH9: =SUM(AH14:AH180) -> 0 | AI9: =SUM(AF9:AH9) -> 0 | AJ9: =SUM(AJ14:AJ176) -> 0 | AK9: =SUM(AK14:AK176) -> 0 | AL9: =SUM(AL14:AL176) -> 0 | AM9: =SUM(AJ9:AL9) -> 0 | AN9: =SUM(AN14:AN176) -> 0 | AO9: =SUM(AO14:AO176) -> 0 | AP9: =SUM(AP14:AP176) -> 0 | AQ9: =SUM(AN9:AP9) -> 0 | AR9: =SUM(AR14:AR180) -> 0 | AS9: =SUM(AS14:AS180) -> 0 | AT9: =SUM(AT14:AT180) -> 0 | AU9: =SUM(AR9:AT9) -> 0 | AV9: =SUM(AV14:AV176) -> 0 | AW9: =SUM(AW14:AW176) -> 0 | AX9: =SUM(AX14:AX176) -> 0 | AY9: =SUM(AV9:AX9) -> 0 | AZ9: =SUM(AZ14:AZ87) -> 0
A10: A.2.22 - UV 05 EG Unterrichtsbereich
A12: Kabel/ Stromkreis
